<?xml version="1.0"?>
<robot>
    <!-- /////////////////////////////////////// LINKS /////////////////////////////////////// -->
    <!-- LINK_WHEEL MACRO -->
    <macro name="link_wheel" params="name">
        <link name="${name}">
            <inertial>
                <mass value="0.2"/>
                <origin rpy="0 1.5707 1.5707" xyz="0 0 0"/>
                <inertia ixx="0.000526666666667" ixy="0" ixz="0" iyy="0.000526666666667" iyz="0" izz="0.001"/>
            </inertial>
            <collision name="${name}_collision">
                <origin rpy="0 1.5707 1.5707" xyz="0 0 0"/>
                <geometry>
                    <cylinder length="0.04" radius="0.1"/>
                </geometry>
            </collision>
            <visual name="${name}_visual">
                <origin rpy="0 1.5707 1.5707" xyz="0 0 0"/>
                <geometry>
                    <cylinder length="0.04" radius="0.1"/>
                </geometry>
            </visual>
        </link>
    </macro>
    <!-- JOINT_WHEEL MACRO -->
    <macro name="joint_wheel" params="name child origin_xyz">
        <joint name="${name}" type="continuous">
            <origin rpy="0 0 0" xyz="${origin_xyz}"/>
            <child link="${child}"/>
            <parent link="link_chassis"/>
            <axis rpy="0 0 0" xyz="0 1 0"/>
            <limit effort="10000" velocity="1000"/>
            <joint_properties damping="1.0" friction="1.0"/>
        </joint>
    </macro>

    <macro name="cylinder_inertia" params="mass r l">
        <inertia ixx ="${mass*(3*r*r+l*l)/12}" ixy = "0" ixz="0"
                 iyy ="${mass*(3*r*r+l*l)/12}" iyz="0"
                 izz ="${mass*(3*r*r+l*l)/12}" />
    </macro>

    <!-- /////////////////////////////////////// LASER SENSOR GAZEBO PLUGIN /////////////////////////////////////// -->
    <!-- <gazebo reference="sensor_laser">
        <sensor type="ray" name="head_hokuyo_sensor">
            <pose>0 0 0 0 0 0</pose>
            <visualize>false</visualize>
            <update_rate>20</update_rate>
            <ray>
                <scan>
                    <horizontal>
                        <samples>720</samples>
                        <resolution>1</resolution>
                        <min_angle>-1.570796</min_angle>
                        <max_angle>1.570796</max_angle>
                    </horizontal>
                </scan>
                <range>
                    <min>0.10</min>
                    <max>10.0</max>
                    <resolution>0.01</resolution>
                </range>
                <noise>
                    <type>gaussian</type>
                    <mean>0.0</mean>
                    <stddev>0.01</stddev>
                </noise>
            </ray>
            <plugin name="gazebo_ros_head_hokuyo_controller" filename="libgazebo_ros_laser.so">
                <topicName>/m2wr/laser/scan</topicName>
                <frameName>sensor_laser</frameName>
            </plugin>
        </sensor>
    </gazebo> -->

</robot>